{"trial_id": "0001", "hyperparameters": {"space": [{"class_name": "Int", "config": {"name": "filters_1", "default": null, "conditions": [], "min_value": 32, "max_value": 128, "step": 32, "sampling": "linear"}}, {"class_name": "Int", "config": {"name": "filters_2", "default": null, "conditions": [], "min_value": 64, "max_value": 256, "step": 64, "sampling": "linear"}}, {"class_name": "Int", "config": {"name": "units_1", "default": null, "conditions": [], "min_value": 128, "max_value": 512, "step": 128, "sampling": "linear"}}, {"class_name": "Choice", "config": {"name": "optimizer", "default": "adam", "conditions": [], "values": ["adam", "sgd"], "ordered": false}}], "values": {"filters_1": 96, "filters_2": 64, "units_1": 128, "optimizer": "adam", "tuner/epochs": 2, "tuner/initial_epoch": 0, "tuner/bracket": 2, "tuner/round": 0}}, "metrics": {"metrics": {}}, "score": null, "best_step": 0, "status": "FAILED", "message": "Traceback (most recent call last):\n  File \"C:\\Users\\josep\\AppData\\Local\\Programs\\Python\\Python312\\Lib\\site-packages\\keras_tuner\\src\\engine\\base_tuner.py\", line 274, in _try_run_and_update_trial\n    self._run_and_update_trial(trial, *fit_args, **fit_kwargs)\n  File \"C:\\Users\\josep\\AppData\\Local\\Programs\\Python\\Python312\\Lib\\site-packages\\keras_tuner\\src\\engine\\base_tuner.py\", line 239, in _run_and_update_trial\n    results = self.run_trial(trial, *fit_args, **fit_kwargs)\n              ^^^^^^^^^^^^^^^^^^^^^^^^^^^^^^^^^^^^^^^^^^^^^^\n  File \"C:\\Users\\josep\\AppData\\Local\\Programs\\Python\\Python312\\Lib\\site-packages\\keras_tuner\\src\\tuners\\hyperband.py\", line 427, in run_trial\n    return super().run_trial(trial, *fit_args, **fit_kwargs)\n           ^^^^^^^^^^^^^^^^^^^^^^^^^^^^^^^^^^^^^^^^^^^^^^^^^\n  File \"C:\\Users\\josep\\AppData\\Local\\Programs\\Python\\Python312\\Lib\\site-packages\\keras_tuner\\src\\engine\\tuner.py\", line 314, in run_trial\n    obj_value = self._build_and_fit_model(trial, *args, **copied_kwargs)\n                ^^^^^^^^^^^^^^^^^^^^^^^^^^^^^^^^^^^^^^^^^^^^^^^^^^^^^^^^\n  File \"C:\\Users\\josep\\AppData\\Local\\Programs\\Python\\Python312\\Lib\\site-packages\\keras_tuner\\src\\engine\\tuner.py\", line 233, in _build_and_fit_model\n    results = self.hypermodel.fit(hp, model, *args, **kwargs)\n              ^^^^^^^^^^^^^^^^^^^^^^^^^^^^^^^^^^^^^^^^^^^^^^^\n  File \"C:\\Users\\josep\\AppData\\Local\\Programs\\Python\\Python312\\Lib\\site-packages\\keras_tuner\\src\\engine\\hypermodel.py\", line 149, in fit\n    return model.fit(*args, **kwargs)\n           ^^^^^^^^^^^^^^^^^^^^^^^^^^\n  File \"C:\\Users\\josep\\AppData\\Local\\Programs\\Python\\Python312\\Lib\\site-packages\\keras\\src\\utils\\traceback_utils.py\", line 122, in error_handler\n    raise e.with_traceback(filtered_tb) from None\n  File \"C:\\Users\\josep\\AppData\\Local\\Programs\\Python\\Python312\\Lib\\site-packages\\tensorflow\\python\\eager\\execute.py\", line 59, in quick_execute\n    except TypeError as e:\ntensorflow.python.framework.errors_impl.InvalidArgumentError: Graph execution error:\n\nDetected at node compile_loss/sparse_categorical_crossentropy/SparseSoftmaxCrossEntropyWithLogits/SparseSoftmaxCrossEntropyWithLogits defined at (most recent call last):\n  File \"<string>\", line 1, in <module>\n\n  File \"C:\\Users\\josep\\AppData\\Local\\Programs\\Python\\Python312\\Lib\\idlelib\\run.py\", line 165, in main\n\n  File \"C:\\Users\\josep\\AppData\\Local\\Programs\\Python\\Python312\\Lib\\idlelib\\run.py\", line 580, in runcode\n\n  File \"C:/Users/josep/Documents/GitHub/MachineLearning/Hallieughya.py\", line 150, in <module>\n\n  File \"C:/Users/josep/Documents/GitHub/MachineLearning/Hallieughya.py\", line 142, in main_menu\n\n  File \"C:/Users/josep/Documents/GitHub/MachineLearning/Hallieughya.py\", line 119, in train_and_evaluate\n\n  File \"C:/Users/josep/Documents/GitHub/MachineLearning/Hallieughya.py\", line 104, in hyperparameter_tuning\n\n  File \"C:\\Users\\josep\\AppData\\Local\\Programs\\Python\\Python312\\Lib\\site-packages\\keras_tuner\\src\\engine\\base_tuner.py\", line 234, in search\n\n  File \"C:\\Users\\josep\\AppData\\Local\\Programs\\Python\\Python312\\Lib\\site-packages\\keras_tuner\\src\\engine\\base_tuner.py\", line 274, in _try_run_and_update_trial\n\n  File \"C:\\Users\\josep\\AppData\\Local\\Programs\\Python\\Python312\\Lib\\site-packages\\keras_tuner\\src\\engine\\base_tuner.py\", line 239, in _run_and_update_trial\n\n  File \"C:\\Users\\josep\\AppData\\Local\\Programs\\Python\\Python312\\Lib\\site-packages\\keras_tuner\\src\\tuners\\hyperband.py\", line 427, in run_trial\n\n  File \"C:\\Users\\josep\\AppData\\Local\\Programs\\Python\\Python312\\Lib\\site-packages\\keras_tuner\\src\\engine\\tuner.py\", line 314, in run_trial\n\n  File \"C:\\Users\\josep\\AppData\\Local\\Programs\\Python\\Python312\\Lib\\site-packages\\keras_tuner\\src\\engine\\tuner.py\", line 233, in _build_and_fit_model\n\n  File \"C:\\Users\\josep\\AppData\\Local\\Programs\\Python\\Python312\\Lib\\site-packages\\keras_tuner\\src\\engine\\hypermodel.py\", line 149, in fit\n\n  File \"C:\\Users\\josep\\AppData\\Local\\Programs\\Python\\Python312\\Lib\\site-packages\\keras\\src\\utils\\traceback_utils.py\", line 117, in error_handler\n\n  File \"C:\\Users\\josep\\AppData\\Local\\Programs\\Python\\Python312\\Lib\\site-packages\\keras\\src\\backend\\tensorflow\\trainer.py\", line 318, in fit\n\n  File \"C:\\Users\\josep\\AppData\\Local\\Programs\\Python\\Python312\\Lib\\site-packages\\keras\\src\\backend\\tensorflow\\trainer.py\", line 121, in one_step_on_iterator\n\n  File \"C:\\Users\\josep\\AppData\\Local\\Programs\\Python\\Python312\\Lib\\site-packages\\keras\\src\\backend\\tensorflow\\trainer.py\", line 108, in one_step_on_data\n\n  File \"C:\\Users\\josep\\AppData\\Local\\Programs\\Python\\Python312\\Lib\\site-packages\\keras\\src\\backend\\tensorflow\\trainer.py\", line 54, in train_step\n\n  File \"C:\\Users\\josep\\AppData\\Local\\Programs\\Python\\Python312\\Lib\\site-packages\\keras\\src\\trainers\\trainer.py\", line 357, in _compute_loss\n\n  File \"C:\\Users\\josep\\AppData\\Local\\Programs\\Python\\Python312\\Lib\\site-packages\\keras\\src\\trainers\\trainer.py\", line 325, in compute_loss\n\n  File \"C:\\Users\\josep\\AppData\\Local\\Programs\\Python\\Python312\\Lib\\site-packages\\keras\\src\\trainers\\compile_utils.py\", line 609, in __call__\n\n  File \"C:\\Users\\josep\\AppData\\Local\\Programs\\Python\\Python312\\Lib\\site-packages\\keras\\src\\trainers\\compile_utils.py\", line 645, in call\n\n  File \"C:\\Users\\josep\\AppData\\Local\\Programs\\Python\\Python312\\Lib\\site-packages\\keras\\src\\losses\\loss.py\", line 43, in __call__\n\n  File \"C:\\Users\\josep\\AppData\\Local\\Programs\\Python\\Python312\\Lib\\site-packages\\keras\\src\\losses\\losses.py\", line 27, in call\n\n  File \"C:\\Users\\josep\\AppData\\Local\\Programs\\Python\\Python312\\Lib\\site-packages\\keras\\src\\losses\\losses.py\", line 1853, in sparse_categorical_crossentropy\n\n  File \"C:\\Users\\josep\\AppData\\Local\\Programs\\Python\\Python312\\Lib\\site-packages\\keras\\src\\ops\\nn.py\", line 1567, in sparse_categorical_crossentropy\n\n  File \"C:\\Users\\josep\\AppData\\Local\\Programs\\Python\\Python312\\Lib\\site-packages\\keras\\src\\backend\\tensorflow\\nn.py\", line 645, in sparse_categorical_crossentropy\n\nReceived a label value of 631 which is outside the valid range of [0, 10).  Label values: 621 577 268 404 591 601 375 97 631 226 182 487 105 382 595 125 413 450 248 5 1 149 203 218 534 458 118 366 18 2 184 234\n\t [[{{node compile_loss/sparse_categorical_crossentropy/SparseSoftmaxCrossEntropyWithLogits/SparseSoftmaxCrossEntropyWithLogits}}]] [Op:__inference_one_step_on_iterator_2374]\n"}